Workbook

Sheet Staging >>>

Sheet Requirements
A1: Requirement ID | B1: Requirement | C1: Epic ID | D1: Epic Name | E1: Business Role | F1: Additional Commentary | G1: A6 Reference (JS) | H1: ZR Only
B2: Generate a report of customers, their credit limits and whether they are exceeding the credit limit | C2: Q2C-010-040 | D2: Perform Periodic Credit Review | E2: Credit Officer
B3: Place an active customer on Hold | C3: Q2C-010-040 | D3: Perform Periodic Credit Review | E3: Credit Officer | F3: -Placing a customer on hold requires a reason - If the person putting a customer on hold is not a customer administrator then it will go for approval by a customer administrator - A credit officer may not be a customer administrator
B4: Make a customer inactive | C4: Q2C-010-050 | D4: Perform Customer Closure | E4: Accounts Recievable Officer | F4: No approvals needed for the accounts receivable officer
B5: Where a customer has an on-account balance, the balance needs to be written up to the balance sheet | C5: Q2C-010-050 | D5: Perform Customer Closure | E5: Accounts Recievable Officer | F5: In workday the teminology for a "write up" is the "Customer overpayment" business process
B6: Request a Customer Contract creation in Service Now | C6: Q2C-020-010 | D6: Establish Contract Portfolio Management | E6: Business User
B7: Create a customer contract in Workday | C7: Q2C-020-010 | D7: Establish Contract Portfolio Management | E7: Accounts Recievable Officer | F7: One example of a customer contract that would be created is a Property Rental Contract
B8: Where a contract has a defined billing schedule this should be associated with the created customer contract | C8: Q2C-020-010 | D8: Establish Contract Portfolio Management | E8: Accounts Recievable Officer | F8: A customer contract must already be in the system
B9: Where a contract is flagged as deferred revenue, a revenue recognition schedule needs to be created | C9: Q2C-020-010 | D9: Establish Contract Portfolio Management | E9: Revenue Specialist
B10: Process an amendment to an existing contract | C10: Q2C-020-030 | D10: Manage Contract Compliance and Administration | E10: Accounts Recievable Officer | F10: - the amendment will be a dollar amount - the amendment will affect the already defined billing schedule
B11: Report that a contract has issued all invoices and billed to the maximum amount of the contract | C11: Q2C-020-040 | D11: Close Out Contract | E11: Accounts Recievable Officer
B12: Ability to update and change a customers payment terms | C12: Q2C-040-010 | D12: Manage Billing and Payment Methods | E12: Accounts Recievable Officer
B13: Ability to change an existing billing schedule to have different terms of payment | C13: Q2C-040-010 | D13: Manage Billing and Payment Methods | E13: Accounts Recievable Officer
B14: Ability to request a customer invoice to be created by the Accounts Receivable Team | C14: Q2C-040-020 | D14: Generate, Review & Approve Invoice | E14: Business User | F14: This occurs in Service Now
A15: REQ001 | B15: Ability to process a standalone customer invoice based on a request from the business | C15: Q2C-040-020 | D15: Generate, Review & Approve Invoice | E15: Accounts Recievable Officer | F15: A customer invoice can also have attachments that the user can select are issued to the customer as an attachment, or kept internally
A16: REQ002 | B16: Ability to process a standalone customer invoice based on a request from the business | C16: Q2C-040-020 | D16: Generate, Review & Approve Invoice | E16: Accounts Recievable Officer | F16: - A warning is shown if the customers credit limit is exceeded - A warning is shown if the customer is set to mail delivery - A warning is shown if the invoice date is not todays date
A17: REQ003 | B17: Ability to process a student sponsorship invoice | C17: Q2C-040-020 | D17: Generate, Review & Approve Invoice | E17: Accounts Recievable Officer | F17: -a sponsorship invoice is for capturing income for student placements by a third party and is to be captured as a specific scenario
A18: REQ004 | B18: Ability to automatically generate an invoice based on a customer contracts billing schedule | C18: Q2C-040-020 | D18: Generate, Review & Approve Invoice | E18: Accounts Recievable Officer | F18: - this will be for a rental customer contract; where the rental invoices have a different printed invoice layout
B19: Where an invoice has deferred revenue, a revenue recognition schedule is to be created | C19: Q2C-040-020 | D19: Generate, Review & Approve Invoice | E19: Revenue Specialist
B20: Ability to email an invoice to a customer | C20: Q2C-040-030 | D20: Distribute Invoice | E20: Accounts Recievable Officer | F20: - Emailing the invoice occurs immediately after processing the invoice - the invoice will be created as a PDF and stored in Workday -if the customer is not setup to receive emails then the system will prompt the Accounts Recievable officer to update the customer record - the customer record is to be updated before the system will let you send an email
B21: Abilty to generate an invoice without sending the invoice as an email | C21: Q2C-040-030 | D21: Distribute Invoice | E21: Accounts Recievable Officer | F21: - the invoice can be generated as a PDF manually
B22: Ability to update a purchase order number onto the customer invoice after it was generated | C22: Q2C-040-030 | D22: Distribute Invoice | E22: Accounts Recievable Officer | F22: the invoice print can be regenerated with the updated purchase order number visible
B23: Ability to schedule customer statements being sent monthly | C23: Q2C-040-040 | D23: Generate and Distribute Statements | E23: Accounts Recievable Officer
B24: Ability to generate a customer statement and manually email it to a customer | C24: Q2C-040-040 | D24: Generate and Distribute Statements | E24: Accounts Recievable Officer
B25: Ability to generate a customer statement and have the system email it to the customer | C25: Q2C-040-040 | D25: Generate and Distribute Statements | E25: Accounts Recievable Officer | F25: -if the customer is not setup to receive emails then the system will prompt the Accounts Recievable officer to update the customer record - the customer record is to be updated before the system will let you send an email
B26: Ability to mark invoices as in dispute and provide reason, and free text notes | C26: Q2C-050-010 | D26: Manage Customer Service Inquiry and Orders | E26: Credit Officer | F26: This can be done en masse and also for an individual invoice
B27: Ability to resolve the dispute and mark the invoice as such | C27: Q2C-050-010 | D27: Manage Customer Service Inquiry and Orders | E27: Credit Officer
B28: Ability to resolve the dispute and mark the invoice as such | C28: Q2C-050-020 | D28: Manage Customer Service Inquiry and Orders | E28: Credit Officer
B29: ability to create a credit note | C29: Q2C-050-030 | D29: Process Charge Backs & credit memos | E29: Accounts Recievable Officer | F29: a credit note can be associated with a customer invoice or can be freestanding
B30: Ability to create a rebill invoice and automatically have a credit note generated to offset the original invoice | C30: Q2C-050-030 | D30: Process Charge Backs & credit memos | E30: Accounts Recievable Officer
B31: Where a credit note is against the customer account I need to be able to issue a refund to the customer | C31: Q2C-050-030 | D31: Process Charge Backs & credit memos | E31: Accounts Recievable Officer | F31: - a refund will require the customer to have their bank account added to the customer record so that a refund can be processed '- adding a bank account requires an approval by a different Accounts Receivable officer due to segregation of duties
B32: ability to check if a customer has a bank account already associated with the customer record | C32: Q2C-050-030 | D32: Process Charge Backs & credit memos | E32: Accounts Recievable Officer
B33: Automatically process customer payments based on the bank statement being imported into workday | C33: Q2C-060-010 | D33: Process Payments & Apply Receipts | E33: System | F33: These will be created only if the format of the addenda on the bank statement line follows the Customer Invoice ID (e.g. CIV00001)
B34: Manually create a customer payment based on reviewing the bank statement line | C34: Q2C-060-010 | D34: Process Payments & Apply Receipts | E34: bank Reconciliation Officer | F34: A customer payment may or may not contain remittance advice to be input within Workday
B35: Where a customer payment cannot be associated with an invoice it is to be placed on the customers account | C35: Q2C-060-010 | D35: Process Payments & Apply Receipts | E35: bank Reconciliation Officer
B36: Where a customer payment does not entirely offset the invoice amount, the invoice will be automatically written off | C36: Q2C-060-010 | D36: Process Payments & Apply Receipts | E36: System | F36: - The small amount is written off to a central cost center not the invoices original cost center - This only occurs when the invoice has a remaining balance of less than $1 after a payment is applied
B37: Ability to look at loaded bank statements to identify potential customer payments | C37: Q2C-060-020 | D37: Reconcile Unapplied, Misapplied, and Unidentified Payments | E37: bank Reconciliation Officer
B38: Ability to unapply a payment and apply to a different invoice | C38: Q2C-060-020 | D38: Reconcile Unapplied, Misapplied, and Unidentified Payments | E38: bank Reconciliation Officer
B39: ability to update the remittance advice of an already recorded payment to then apply to an invoice if the payment is on account | C39: Q2C-060-020 | D39: Reconcile Unapplied, Misapplied, and Unidentified Payments | E39: bank Reconciliation Officer | F39: this can be done by either the user manually or automatically through a system process called "Auto Apply Customer Payments"
B40: ability to run a receivables aging report | C40: Q2C-070-020 | D40: Perform Collection Activity | E40: Credit Officer
...

Sheet Output >>>

Sheet Taxonomy and Epics
A1: Area | B1: Numbering | C1: Code | D1: Naming | E1: Level 1 Service | F1: L2 Code | G1: Level 2 Service Name | H1: L3 Code (EPIC) | I1: Level 3 Process Name | J1: >>> | K1: Number of User Stories
A2: Finance | B2: 1.0 | C2: FGV | D2: Finance Governance | E2: =B2&" - "&C2&" - "&D2 -> 1.0 - FGV - Finance Governance | F2: =LEFT(H2,7) -> GOV-010 | G2: Data Management | H2: GOV-010-01 | I2: Maintain Data Model (Chart of Accounts, Dimensions, Hierarchies) | K2: =COUNTIF('User Stories'!H:H,'Taxonomy and Epics'!H2) -> 0
A3: Finance | B3: 1.0 | C3: FGV | D3: Finance Governance | E3: =B3&" - "&C3&" - "&D3 -> 1.0 - FGV - Finance Governance | F3: =LEFT(H3,7) -> GOV-010 | G3: Data Management | H3: GOV-010-02 | I3: Maintain Master Data | K3: =COUNTIF('User Stories'!H:H,'Taxonomy and Epics'!H3) -> 0
A4: Finance | B4: 1.0 | C4: FGV | D4: Finance Governance | E4: =B4&" - "&C4&" - "&D4 -> 1.0 - FGV - Finance Governance | F4: =LEFT(H4,7) -> GOV-010 | G4: Data Management | H4: GOV-010-03 | I4: Maintain Reports | K4: =COUNTIF('User Stories'!H:H,'Taxonomy and Epics'!H4) -> 0
A5: Finance | B5: 1.0 | C5: FGV | D5: Finance Governance | E5: =B5&" - "&C5&" - "&D5 -> 1.0 - FGV - Finance Governance | F5: =LEFT(H5,7) -> GOV-020 | G5: Application and Interface Management & Maintenance | H5: GOV-020-010 | I5: Maintain Application Configuration & Security | K5: =COUNTIF('User Stories'!H:H,'Taxonomy and Epics'!H5) -> 0
A6: Finance | B6: 1.0 | C6: FGV | D6: Finance Governance | E6: =B6&" - "&C6&" - "&D6 -> 1.0 - FGV - Finance Governance | F6: =LEFT(H6,7) -> GOV-020 | G6: Application and Interface Management & Maintenance | H6: GOV-020-020 | I6: Manage Application Releases & Upgrades | K6: =COUNTIF('User Stories'!H:H,'Taxonomy and Epics'!H6) -> 0
A7: Finance | B7: 1.0 | C7: FGV | D7: Finance Governance | E7: =B7&" - "&C7&" - "&D7 -> 1.0 - FGV - Finance Governance | F7: =LEFT(H7,7) -> GOV-020 | G7: Application and Interface Management & Maintenance | H7: GOV-020-030 | I7: Manage Interfaces | K7: =COUNTIF('User Stories'!H:H,'Taxonomy and Epics'!H7) -> 0
A8: Finance | B8: 1.0 | C8: FGV | D8: Finance Governance | E8: =B8&" - "&C8&" - "&D8 -> 1.0 - FGV - Finance Governance | F8: =LEFT(H8,7) -> GOV-030 | G8: Automation | H8: GOV-030-010 | I8: Maintain Process Automation | K8: =COUNTIF('User Stories'!H:H,'Taxonomy and Epics'!H8) -> 0
A9: Finance | B9: 1.0 | C9: FGV | D9: Finance Governance | E9: =B9&" - "&C9&" - "&D9 -> 1.0 - FGV - Finance Governance | F9: =LEFT(H9,7) -> GOV-04- | G9: Admin and Records Management | H9: GOV-04-010 | I9: Manage Planning/ Forecast Calendar | K9: =COUNTIF('User Stories'!H:H,'Taxonomy and Epics'!H9) -> 0
A10: Finance | B10: 1.0 | C10: FGV | D10: Finance Governance | E10: =B10&" - "&C10&" - "&D10 -> 1.0 - FGV - Finance Governance | F10: =LEFT(H10,7) -> GOV-040 | G10: Admin and Records Management | H10: GOV-040-020 | I10: Manage Close Process & Calendar | K10: =COUNTIF('User Stories'!H:H,'Taxonomy and Epics'!H10) -> 0
A11: Finance | B11: 1.0 | C11: FGV | D11: Finance Governance | E11: =B11&" - "&C11&" - "&D11 -> 1.0 - FGV - Finance Governance | F11: =LEFT(H11,7) -> GOV-040 | G11: Admin and Records Management | H11: GOV-040-030 | I11: Archive & Maintain Records | K11: =COUNTIF('User Stories'!H:H,'Taxonomy and Epics'!H11) -> 0
A12: Finance | B12: 1.0 | C12: FGV | D12: Finance Governance | E12: =B12&" - "&C12&" - "&D12 -> 1.0 - FGV - Finance Governance | F12: =LEFT(H12,7) -> GOV-050 | G12: Compliance and Controls | H12: GOV-050-010 | I12: Maintain Policies, Procedures, & Templates | K12: =COUNTIF('User Stories'!H:H,'Taxonomy and Epics'!H12) -> 0
A13: Finance | B13: 1.0 | C13: FGV | D13: Finance Governance | E13: =B13&" - "&C13&" - "&D13 -> 1.0 - FGV - Finance Governance | F13: =LEFT(H13,7) -> GOV-050 | G13: Compliance and Controls | H13: GOV-050-020 | I13: Maintain Internal Controls | K13: =COUNTIF('User Stories'!H:H,'Taxonomy and Epics'!H13) -> 0
... A16: Finance | B16: 1.0 | C16: FGV | D16: Finance Governance | E16: =B16&" - "&C16&" - "&D16 -> 1.0 - FGV - Finance Governance | F16: =LEFT(H16,7) -> GOV-060 | G16: Process Efficiency | H16: GOV-060-010 | I16: Manage Process Efficiency & Effectiveness | K16: =COUNTIF('User Stories'!H:H,'Taxonomy and Epics'!H16) -> 0
A17: Finance | B17: 1.0 | C17: FGV | D17: Finance Governance | E17: =B17&" - "&C17&" - "&D17 -> 1.0 - FGV - Finance Governance | F17: =LEFT(H17,7) -> GOV-060 | G17: Process Efficiency | H17: GOV-060-020 | I17: Enhance Business Partner/ Employee Experience
A18: Finance | B18: 1.0 | C18: FGV | D18: Finance Governance | E18: =B18&" - "&C18&" - "&D18 -> 1.0 - FGV - Finance Governance | F18: =LEFT(H18,7) -> GOV-060 | G18: Process Efficiency | H18: GOV-060-030 | I18: Retain & Update Predictive Models
A19: Finance | B19: 10.0 | C19: TRE | D19: Treasury | E19: =B19&" - "&C19&" - "&D19 -> 10.0 - TRE - Treasury | F19: =LEFT(H19,7) -> TRE-010 | G19: Treasury Administration | H19: TRE-010-010 | I19: Manage Bank Accounts | K19: =COUNTIF('User Stories'!H:H,'Taxonomy and Epics'!H19) -> 1
A20: Finance | B20: 10.0 | C20: TRE | D20: Treasury | E20: =B20&" - "&C20&" - "&D20 -> 10.0 - TRE - Treasury | F20: =LEFT(H20,7) -> TRE-010 | G20: Treasury Administration | H20: TRE-010-020 | I20: Treasury and Liquidity Reporting | K20: =COUNTIF('User Stories'!H:H,'Taxonomy and Epics'!H20) -> 0
A21: Finance | B21: 10.0 | C21: TRE | D21: Treasury | E21: =B21&" - "&C21&" - "&D21 -> 10.0 - TRE - Treasury | F21: =LEFT(H21,7) -> TRE-010 | G21: Treasury Administration | H21: TRE-010-030 | I21: Manage and Report Debt Covenants | K21: =COUNTIF('User Stories'!H:H,'Taxonomy and Epics'!H21) -> 0
A22: Finance | B22: 10.0 | C22: TRE | D22: Treasury | E22: =B22&" - "&C22&" - "&D22 -> 10.0 - TRE - Treasury | F22: =LEFT(H22,7) -> TRE-010 | G22: Treasury Administration | H22: TRE-010-040 | I22: Manage Banking Relationships | K22: =COUNTIF('User Stories'!H:H,'Taxonomy and Epics'!H22) -> 0
A23: Finance | B23: 10.0 | C23: TRE | D23: Treasury | E23: =B23&" - "&C23&" - "&D23 -> 10.0 - TRE - Treasury | F23: =LEFT(H23,7) -> TRE-020 | G23: Cash and Liquidity Management | H23: TRE-020-010 | I23: Manage Bank Account Cash Balances | K23: =COUNTIF('User Stories'!H:H,'Taxonomy and Epics'!H23) -> 7
A24: Finance | B24: 10.0 | C24: TRE | D24: Treasury | E24: =B24&" - "&C24&" - "&D24 -> 10.0 - TRE - Treasury | F24: =LEFT(H24,7) -> TRE-020 | G24: Cash and Liquidity Management | H24: TRE-020-020 | I24: Cash Management Reporting and Analytics | K24: =COUNTIF('User Stories'!H:H,'Taxonomy and Epics'!H24) -> 0
A25: Finance | B25: 10.0 | C25: TRE | D25: Treasury | E25: =B25&" - "&C25&" - "&D25 -> 10.0 - TRE - Treasury | F25: =LEFT(H25,7) -> TRE-030 | G25: Bank Reconciliations | H25: TRE-030-010 | I25: Perform Bank Reconciliation | K25: =COUNTIF('User Stories'!H:H,'Taxonomy and Epics'!H25) -> 13
A26: Finance | B26: 10.0 | C26: TRE | D26: Treasury | E26: =B26&" - "&C26&" - "&D26 -> 10.0 - TRE - Treasury | F26: =LEFT(H26,7) -> TRE-030 | G26: Bank Reconciliations | H26: TRE-030-020 | I26: Process Book-to-Bank Reconciliation | K26: =COUNTIF('User Stories'!H:H,'Taxonomy and Epics'!H26) -> 0
A27: Finance | B27: 10.0 | C27: TRE | D27: Treasury | E27: =B27&" - "&C27&" - "&D27 -> 10.0 - TRE - Treasury | F27: =LEFT(H27,7) -> TRE-040 | G27: Settlement & Payment | H27: TRE-040-010 | I27: Process Payment Return Statements | K27: =COUNTIF('User Stories'!H:H,'Taxonomy and Epics'!H27) -> 4
A28: Finance | B28: 10.0 | C28: TRE | D28: Treasury | E28: =B28&" - "&C28&" - "&D28 -> 10.0 - TRE - Treasury | F28: =LEFT(H28,7) -> TRE-040 | G28: Settlement & Payment | H28: TRE-040-020 | I28: Process Stopped Payments | K28: =COUNTIF('User Stories'!H:H,'Taxonomy and Epics'!H28) -> 1
A29: Finance | B29: 10.0 | C29: TRE | D29: Treasury | E29: =B29&" - "&C29&" - "&D29 -> 10.0 - TRE - Treasury | F29: =LEFT(H29,7) -> TRE-040 | G29: Settlement & Payment | H29: TRE-040-040 | I29: Manage Intercompany Settlements | K29: =COUNTIF('User Stories'!H:H,'Taxonomy and Epics'!H29) -> 0
A30: Finance | B30: 10.0 | C30: TRE | D30: Treasury | E30: =B30&" - "&C30&" - "&D30 -> 10.0 - TRE - Treasury | F30: =LEFT(H30,7) -> TRE-050 | G30: Debt, Investment & Equity Management | H30: TRE-050-010 | I30: Manage Treasury, Debt and Capital Markets | K30: =COUNTIF('User Stories'!H:H,'Taxonomy and Epics'!H30) -> 0
... A79: Finance | B79: 2.0 | C79: PLN | D79: Plan to Perform | E79: =B79&" - "&C79&" - "&D79 -> 2.0 - PLN - Plan to Perform | F79: =LEFT(H79,7) -> P2P-080 | G79: Agree Action Plans & Update Forecast | H79: P2P-080-040 | I79: Update Business & External Drivers | K79: =COUNTIF('User Stories'!H:H,'Taxonomy and Epics'!H79) -> 0
A80: Finance | B80: 2.0 | C80: PLN | D80: Plan to Perform | E80: =B80&" - "&C80&" - "&D80 -> 2.0 - PLN - Plan to Perform | F80: =LEFT(H80,7) -> P2P-080 | G80: Agree Action Plans & Update Forecast | H80: P2P-080-050 | I80: Update Forecast & Performance Targets
A81: Finance | B81: 2.0 | C81: PLN | D81: Plan to Perform | E81: =B81&" - "&C81&" - "&D81 -> 2.0 - PLN - Plan to Perform | F81: =LEFT(H81,7) -> P2P-080 | G81: Agree Action Plans & Update Forecast | H81: P2P-080-060 | I81: Input to External Guidance
A82: Finance | B82: 3.0 | C82: Q2C | D82: Quote to Cash | E82: =B82&" - "&C82&" - "&D82 -> 3.0 - Q2C - Quote to Cash | F82: Q2C-010 | G82: Setup Customer & Credit | H82: #N/A | I82: Establish Credit Methodology and Credit Limits | K82: =COUNTIF('User Stories'!H:H,'Taxonomy and Epics'!H82) -> 0
A83: Finance | B83: 3.0 | C83: Q2C | D83: Quote to Cash | E83: =B83&" - "&C83&" - "&D83 -> 3.0 - Q2C - Quote to Cash | F83: Q2C-010 | G83: Setup Customer & Credit | H83: Q2C-010-020 | I83: Process New Customer Credit Application | K83: =COUNTIF('User Stories'!H:H,'Taxonomy and Epics'!H83) -> 3
A84: Finance | B84: 3.0 | C84: Q2C | D84: Quote to Cash | E84: =B84&" - "&C84&" - "&D84 -> 3.0 - Q2C - Quote to Cash | F84: Q2C-010 | G84: Setup Customer & Credit | H84: Q2C-010-030 | I84: Setup Customer Financial Master Data | K84: =COUNTIF('User Stories'!H:H,'Taxonomy and Epics'!H84) -> 5
A85: Finance | B85: 3.0 | C85: Q2C | D85: Quote to Cash | E85: =B85&" - "&C85&" - "&D85 -> 3.0 - Q2C - Quote to Cash | F85: Q2C-010 | G85: Setup Customer & Credit | H85: Q2C-010-040 | I85: Perform Periodic Credit Review | K85: =COUNTIF('User Stories'!H:H,'Taxonomy and Epics'!H85) -> 2
A86: Finance | B86: 3.0 | C86: Q2C | D86: Quote to Cash | E86: =B86&" - "&C86&" - "&D86 -> 3.0 - Q2C - Quote to Cash | F86: Q2C-010 | G86: Setup Customer & Credit | H86: Q2C-010-050 | I86: Perform Customer Closure | K86: =COUNTIF('User Stories'!H:H,'Taxonomy and Epics'!H86) -> 2
A87: Finance | B87: 3.0 | C87: Q2C | D87: Quote to Cash | E87: =B87&" - "&C87&" - "&D87 -> 3.0 - Q2C - Quote to Cash | F87: Q2C-020 | G87: Contract Lifecycle Management (Customer) | H87: Q2C-020-010 | I87: Establish Contract Portfolio Management | K87: =COUNTIF('User Stories'!H:H,'Taxonomy and Epics'!H87) -> 4
A88: Finance | B88: 3.0 | C88: Q2C | D88: Quote to Cash | E88: =B88&" - "&C88&" - "&D88 -> 3.0 - Q2C - Quote to Cash | F88: Q2C-020 | G88: Contract Lifecycle Management (Customer) | H88: #N/A | I88: Manage T&C’s and Contract Templates | K88: =COUNTIF('User Stories'!H:H,'Taxonomy and Epics'!H88) -> 0
A89: Finance | B89: 3.0 | C89: Q2C | D89: Quote to Cash | E89: =B89&" - "&C89&" - "&D89 -> 3.0 - Q2C - Quote to Cash | F89: Q2C-020 | G89: Contract Lifecycle Management (Customer) | H89: Q2C-020-030 | I89: Manage Contract Compliance and Administration | K89: =COUNTIF('User Stories'!H:H,'Taxonomy and Epics'!H89) -> 1
A90: Finance | B90: 3.0 | C90: Q2C | D90: Quote to Cash | E90: =B90&" - "&C90&" - "&D90 -> 3.0 - Q2C - Quote to Cash | F90: Q2C-020 | G90: Contract Lifecycle Management (Customer) | H90: Q2C-020-040 | I90: Close Out Contract | K90: =COUNTIF('User Stories'!H:H,'Taxonomy and Epics'!H90) -> 1
...

Sheet User Stories
A1: User Story ID | B1: High Level Summary | C1: User Story | D1: Acceptance Criteria | E1: Business User | F1: A6 Reference | G1: Linked Requirement | H1: Linked Epic ID | I1: Linked Epic | J1: L1 | K1: L2 Code | L1: L2 | M1: L3 Code | N1: L3 | O1: Integration ID | P1: Integratio Name
A2: 1 | B2: Check if customer exists in ERP during credit application processing | C2: As an AR Officer I want to check if a customer already exists in the ERP, so that I can avoid creating duplicate customer records and process credit applications efficiently. | D2: Given I am processing a new customer credit application, When I enter the customer details, Then the system displays whether the customer exists in the ERP or not. | E2: AR Officer | F2: D.40 | H2: Q2C-010-020 | I2: =_xlfn.XLOOKUP(H2,'Taxonomy and Epics'!H:H,'Taxonomy and Epics'!I:I) -> Process New Customer Credit Application | J2: =_xlfn.XLOOKUP($H2,'Taxonomy and Epics'!$H:$H,'Taxonomy and Epics'!E:E) -> 3.0 - Q2C - Quote to Cash | K2: =_xlfn.XLOOKUP($H2,'Taxonomy and Epics'!$H:$H,'Taxonomy and Epics'!F:F) -> Q2C-010 | L2: =_xlfn.XLOOKUP($H2,'Taxonomy and Epics'!$H:$H,'Taxonomy and Epics'!G:G) -> Setup Customer & Credit | M2: =_xlfn.XLOOKUP($H2,'Taxonomy and Epics'!$H:$H,'Taxonomy and Epics'!H:H) -> Q2C-010-020 | N2: =_xlfn.XLOOKUP($H2,'Taxonomy and Epics'!$H:$H,'Taxonomy and Epics'!I:I) -> Process New Customer Credit Application
A3: 2 | B3: Display stored credit rating for existing customers | C3: As an AR Officer I want to view the stored credit rating for existing customers, so that I can make informed credit decisions based on up-to-date information. | D3: Given the customer exists in the ERP, When I view the customer's credit information, Then the system displays the current credit rating (displayed in the D&B Commercial Credit field) retrieved from Workday. | E3: AR Officer | F3: D.67 | H3: Q2C-010-020 | I3: =_xlfn.XLOOKUP(H3,'Taxonomy and Epics'!H:H,'Taxonomy and Epics'!I:I) -> Process New Customer Credit Application | J3: =_xlfn.XLOOKUP($H3,'Taxonomy and Epics'!$H:$H,'Taxonomy and Epics'!E:E) -> 3.0 - Q2C - Quote to Cash | K3: =_xlfn.XLOOKUP($H3,'Taxonomy and Epics'!$H:$H,'Taxonomy and Epics'!F:F) -> Q2C-010 | L3: =_xlfn.XLOOKUP($H3,'Taxonomy and Epics'!$H:$H,'Taxonomy and Epics'!G:G) -> Setup Customer & Credit | M3: =_xlfn.XLOOKUP($H3,'Taxonomy and Epics'!$H:$H,'Taxonomy and Epics'!H:H) -> Q2C-010-020 | N3: =_xlfn.XLOOKUP($H3,'Taxonomy and Epics'!$H:$H,'Taxonomy and Epics'!I:I) -> Process New Customer Credit Application
A4: 3a | B4: Update Credit Score for existing customer | C4: As an AR Officer I want to update the stored credit rating for an existing customer, so that I can make informed credit decisions based on up-to-date information. | D4: Given the customer exists in the ERP, When I update the customer's credit information, Then the system displays the updated credit rating (displayed in the D&B Commercial Credit field) in Workday. | E4: AR Officer | F4: D.39 | H4: Q2C-010-020 | I4: =_xlfn.XLOOKUP(H4,'Taxonomy and Epics'!H:H,'Taxonomy and Epics'!I:I) -> Process New Customer Credit Application | J4: =_xlfn.XLOOKUP($H4,'Taxonomy and Epics'!$H:$H,'Taxonomy and Epics'!E:E) -> 3.0 - Q2C - Quote to Cash | K4: =_xlfn.XLOOKUP($H4,'Taxonomy and Epics'!$H:$H,'Taxonomy and Epics'!F:F) -> Q2C-010 | L4: =_xlfn.XLOOKUP($H4,'Taxonomy and Epics'!$H:$H,'Taxonomy and Epics'!G:G) -> Setup Customer & Credit | M4: =_xlfn.XLOOKUP($H4,'Taxonomy and Epics'!$H:$H,'Taxonomy and Epics'!H:H) -> Q2C-010-020 | N4: =_xlfn.XLOOKUP($H4,'Taxonomy and Epics'!$H:$H,'Taxonomy and Epics'!I:I) -> Process New Customer Credit Application
A5: 3 | B5: Prevent duplicate customer creation using smart validation | C5: As an AR Officer I want to have smart validation when creating new customers, so that duplicate customers are prevented using checks like primary tax ID (ABN) and name. | D5: Given I am creating a new customer, When I enter customer details, Then the system should validate against existing records using ABN and name and prevent duplicates. | E5: AR Officer | F5: D.39 | G5: D.39 | H5: Q2C-010-030 | I5: =_xlfn.XLOOKUP(H5,'Taxonomy and Epics'!H:H,'Taxonomy and Epics'!I:I) -> Setup Customer Financial Master Data | J5: =_xlfn.XLOOKUP($H5,'Taxonomy and Epics'!$H:$H,'Taxonomy and Epics'!E:E) -> 3.0 - Q2C - Quote to Cash | K5: =_xlfn.XLOOKUP($H5,'Taxonomy and Epics'!$H:$H,'Taxonomy and Epics'!F:F) -> Q2C-010 | L5: =_xlfn.XLOOKUP($H5,'Taxonomy and Epics'!$H:$H,'Taxonomy and Epics'!G:G) -> Setup Customer & Credit | M5: =_xlfn.XLOOKUP($H5,'Taxonomy and Epics'!$H:$H,'Taxonomy and Epics'!H:H) -> Q2C-010-030 | N5: =_xlfn.XLOOKUP($H5,'Taxonomy and Epics'!$H:$H,'Taxonomy and Epics'!I:I) -> Setup Customer Financial Master Data
A6: 4 | B6: Single view of customer record | C6: As an AR Officer I want to see a single view of the customer, so that I can access all relevant information in one place. | D6: Given I am searching for a customer, When I select a customer record, Then I should see a consolidated view of all customer information. | E6: AR Officer | F6: D.41 | G6: D.41 | H6: Q2C-010-030 | I6: =_xlfn.XLOOKUP(H6,'Taxonomy and Epics'!H:H,'Taxonomy and Epics'!I:I) -> Setup Customer Financial Master Data | J6: =_xlfn.XLOOKUP($H6,'Taxonomy and Epics'!$H:$H,'Taxonomy and Epics'!E:E) -> 3.0 - Q2C - Quote to Cash | K6: =_xlfn.XLOOKUP($H6,'Taxonomy and Epics'!$H:$H,'Taxonomy and Epics'!F:F) -> Q2C-010 | L6: =_xlfn.XLOOKUP($H6,'Taxonomy and Epics'!$H:$H,'Taxonomy and Epics'!G:G) -> Setup Customer & Credit | M6: =_xlfn.XLOOKUP($H6,'Taxonomy and Epics'!$H:$H,'Taxonomy and Epics'!H:H) -> Q2C-010-030 | N6: =_xlfn.XLOOKUP($H6,'Taxonomy and Epics'!$H:$H,'Taxonomy and Epics'!I:I) -> Setup Customer Financial Master Data
A7: 5 | B7: Requesting a Customer | C7: As a Business User I want to request a new customer through ServiceNow so that a formal customer creation process is initiated | D7: Given a business user needs a new customer, when they complete the ServiceNow request form, then the request is recorded in ServiceNow and a notification is sent to the AR Officer to start customer creation. | E7: Business User | F7: D.40 | H7: Q2C-010-030 | I7: =_xlfn.XLOOKUP(H7,'Taxonomy and Epics'!H:H,'Taxonomy and Epics'!I:I) -> Setup Customer Financial Master Data | J7: =_xlfn.XLOOKUP($H7,'Taxonomy and Epics'!$H:$H,'Taxonomy and Epics'!E:E) -> 3.0 - Q2C - Quote to Cash | K7: =_xlfn.XLOOKUP($H7,'Taxonomy and Epics'!$H:$H,'Taxonomy and Epics'!F:F) -> Q2C-010 | L7: =_xlfn.XLOOKUP($H7,'Taxonomy and Epics'!$H:$H,'Taxonomy and Epics'!G:G) -> Setup Customer & Credit | M7: =_xlfn.XLOOKUP($H7,'Taxonomy and Epics'!$H:$H,'Taxonomy and Epics'!H:H) -> Q2C-010-030 | N7: =_xlfn.XLOOKUP($H7,'Taxonomy and Epics'!$H:$H,'Taxonomy and Epics'!I:I) -> Setup Customer Financial Master Data
A8: 6 | B8: Creating a Customer In Workday | C8: As an AR Officer I want the system to allow creation of a new customer record in Workday so that the organisation can invoice and manage the customer | D8: 1. Given the AR Officer has valid request data, when they create the customer record, then the customer record is saved in Workday with a unique customer identifier and is available for invoicing and reporting. 2. Given the AR Officer is creating a customer, when they submit the record without a billing address, then the system rejects the save and shows an error indicating the billing address is required. 3. Given the AR Officer is creating or editing a customer, a shipping address is required, then the system uses that shipping address to determine tax defaults on invoices 4. Given the AR Officer is creating a customer, when the customer is save-attempted without a Tax ID, then the system rejects the save and displays an error stating a Tax ID is required; and when a Tax ID is provided, then it is stored and visible on the customer record. 5. Given the AR Officer is creating or updating a customer, when they set the Tax Status, then the chosen status is saved and applied to invoice tax calculations; and when no Tax Status is set, then the system prompts the AR Officer to select one before saving. 6. Given the AR Officer is creating a customer, when they select payment terms, then those terms are saved on the customer record and used as the default on invoices; and when payment terms are missing, then the system blocks saving the record and prompts for terms. 7. Given the AR Officer enters an email for the customer, when the record is saved, then the email is stored on the customer record and available for communications 8. Given the AR officer enters Bank Account details for the customer, when the record is submitted for processing then there is an additional approval by another AR Officer than the initiator | E8: AR Officer | F8: D.289 | G8: D.289 | H8: Q2C-010-030 | I8: =_xlfn.XLOOKUP(H8,'Taxonomy and Epics'!H:H,'Taxonomy and Epics'!I:I) -> Setup Customer Financial Master Data | J8: =_xlfn.XLOOKUP($H8,'Taxonomy and Epics'!$H:$H,'Taxonomy and Epics'!E:E) -> 3.0 - Q2C - Quote to Cash | K8: =_xlfn.XLOOKUP($H8,'Taxonomy and Epics'!$H:$H,'Taxonomy and Epics'!F:F) -> Q2C-010 | L8: =_xlfn.XLOOKUP($H8,'Taxonomy and Epics'!$H:$H,'Taxonomy and Epics'!G:G) -> Setup Customer & Credit | M8: =_xlfn.XLOOKUP($H8,'Taxonomy and Epics'!$H:$H,'Taxonomy and Epics'!H:H) -> Q2C-010-030 | N8: =_xlfn.XLOOKUP($H8,'Taxonomy and Epics'!$H:$H,'Taxonomy and Epics'!I:I) -> Setup Customer Financial Master Data
A9: US001 | B9: Viewing Credit Limits | C9: As a Credit Officer, I want to generate a report on customer credit limits and usage, so that I can proactively manage credit risk. | D9: - Given I have the necessary permissions, when I run the credit review report, then the system displays a list of customers with their credit limits and current outstanding balances. - Given the report is generated, when a customer's balance exceeds their credit limit, then they are clearly flagged in the report. | E9: Credit Officer | F9: D.67 | H9: Q2C-010-040 | I9: =_xlfn.XLOOKUP(H9,'Taxonomy and Epics'!H:H,'Taxonomy and Epics'!I:I) -> Perform Periodic Credit Review | J9: =_xlfn.XLOOKUP($H9,'Taxonomy and Epics'!$H:$H,'Taxonomy and Epics'!E:E) -> 3.0 - Q2C - Quote to Cash | K9: =_xlfn.XLOOKUP($H9,'Taxonomy and Epics'!$H:$H,'Taxonomy and Epics'!F:F) -> Q2C-010 | L9: =_xlfn.XLOOKUP($H9,'Taxonomy and Epics'!$H:$H,'Taxonomy and Epics'!G:G) -> Setup Customer & Credit | M9: =_xlfn.XLOOKUP($H9,'Taxonomy and Epics'!$H:$H,'Taxonomy and Epics'!H:H) -> Q2C-010-040 | N9: =_xlfn.XLOOKUP($H9,'Taxonomy and Epics'!$H:$H,'Taxonomy and Epics'!I:I) -> Perform Periodic Credit Review
A10: US002 | B10: Placing a customer on hold | C10: As a Credit Officer, I want to place a customer on hold, so that I can prevent further transactions until credit issues are resolved. | D10: - Given I am viewing an active customer's record, when I initiate the 'Place on Hold' action, then the system requires me to enter a reason for the hold. - Given I am a Credit Officer (but not a Customer Administrator), when I submit the hold request, then it is routed to an Accounts Receivable Officer (Customer Administrator) for approval. - Given the hold request is approved, then the customer's status is updated to 'On Hold'. | E10: Credit Officer | F10: 0 | H10: Q2C-010-040 | I10: =_xlfn.XLOOKUP(H10,'Taxonomy and Epics'!H:H,'Taxonomy and Epics'!I:I) -> Perform Periodic Credit Review | J10: =_xlfn.XLOOKUP($H10,'Taxonomy and Epics'!$H:$H,'Taxonomy and Epics'!E:E) -> 3.0 - Q2C - Quote to Cash | K10: =_xlfn.XLOOKUP($H10,'Taxonomy and Epics'!$H:$H,'Taxonomy and Epics'!F:F) -> Q2C-010 | L10: =_xlfn.XLOOKUP($H10,'Taxonomy and Epics'!$H:$H,'Taxonomy and Epics'!G:G) -> Setup Customer & Credit | M10: =_xlfn.XLOOKUP($H10,'Taxonomy and Epics'!$H:$H,'Taxonomy and Epics'!H:H) -> Q2C-010-040 | N10: =_xlfn.XLOOKUP($H10,'Taxonomy and Epics'!$H:$H,'Taxonomy and Epics'!I:I) -> Perform Periodic Credit Review
A11: US003 | B11: Making a customer inactive | C11: As an Accounts Receivable Officer, I want to make a customer inactive, so that their record is closed and no new transactions can be processed against it. | D11: - Given I am an Accounts Receivable Officer viewing a customer record, when I initiate the customer summary change process to make a customer 'Inactive', then the system updates the customer's status to 'Inactive' without requiring an approval step. - Given a customer is inactive, when a user attempts to create a new invoice for an 'inactive' customer they are unable to select the record. | E11: Accounts Receivable Officer | F11: 0 | H11: Q2C-010-050 | I11: =_xlfn.XLOOKUP(H11,'Taxonomy and Epics'!H:H,'Taxonomy and Epics'!I:I) -> Perform Customer Closure | J11: =_xlfn.XLOOKUP($H11,'Taxonomy and Epics'!$H:$H,'Taxonomy and Epics'!E:E) -> 3.0 - Q2C - Quote to Cash | K11: =_xlfn.XLOOKUP($H11,'Taxonomy and Epics'!$H:$H,'Taxonomy and Epics'!F:F) -> Q2C-010 | L11: =_xlfn.XLOOKUP($H11,'Taxonomy and Epics'!$H:$H,'Taxonomy and Epics'!G:G) -> Setup Customer & Credit | M11: =_xlfn.XLOOKUP($H11,'Taxonomy and Epics'!$H:$H,'Taxonomy and Epics'!H:H) -> Q2C-010-050 | N11: =_xlfn.XLOOKUP($H11,'Taxonomy and Epics'!$H:$H,'Taxonomy and Epics'!I:I) -> Perform Customer Closure
A12: US004 | B12: writing up an on account balance | C12: As an Accounts Receivable Officer, I want to wite up a customer's on-account credit balance when closing their account, so that the balance is correctly managed. | D12: - Given a customer with an on-account credit is being made inactive, when I process The customer overpayment, then there is a write-up reflected in the P&L - Given a customer with an on-account credit is being made inactive, when I process The customer overpayment, then there is an approval by the shared services manager | E12: Accounts Receivable Officer | F12: 0 | H12: Q2C-010-050 | I12: =_xlfn.XLOOKUP(H12,'Taxonomy and Epics'!H:H,'Taxonomy and Epics'!I:I) -> Perform Customer Closure | J12: =_xlfn.XLOOKUP($H12,'Taxonomy and Epics'!$H:$H,'Taxonomy and Epics'!E:E) -> 3.0 - Q2C - Quote to Cash | K12: =_xlfn.XLOOKUP($H12,'Taxonomy and Epics'!$H:$H,'Taxonomy and Epics'!F:F) -> Q2C-010 | L12: =_xlfn.XLOOKUP($H12,'Taxonomy and Epics'!$H:$H,'Taxonomy and Epics'!G:G) -> Setup Customer & Credit | M12: =_xlfn.XLOOKUP($H12,'Taxonomy and Epics'!$H:$H,'Taxonomy and Epics'!H:H) -> Q2C-010-050 | N12: =_xlfn.XLOOKUP($H12,'Taxonomy and Epics'!$H:$H,'Taxonomy and Epics'!I:I) -> Perform Customer Closure
A13: US005 | B13: Requesting a new customer contract | C13: As a Business User, I want to request the creation of a new customer contract via Service Now, so that the request is formally logged for the Accounts Receivable team to action. | D13: - Given I am in Service Now, when I access the contract request form, then I can enter all necessary details for a new contract. - Given I submit the request, then it is routed to the Accounts Receivable team with all the information needed to create the contract in Workday. | E13: Business User | F13: 0 | H13: Q2C-020-010 | I13: =_xlfn.XLOOKUP(H13,'Taxonomy and Epics'!H:H,'Taxonomy and Epics'!I:I) -> Establish Contract Portfolio Management | J13: =_xlfn.XLOOKUP($H13,'Taxonomy and Epics'!$H:$H,'Taxonomy and Epics'!E:E) -> 3.0 - Q2C - Quote to Cash | K13: =_xlfn.XLOOKUP($H13,'Taxonomy and Epics'!$H:$H,'Taxonomy and Epics'!F:F) -> Q2C-020 | L13: =_xlfn.XLOOKUP($H13,'Taxonomy and Epics'!$H:$H,'Taxonomy and Epics'!G:G) -> Contract Lifecycle Management (Customer) | M13: =_xlfn.XLOOKUP($H13,'Taxonomy and Epics'!$H:$H,'Taxonomy and Epics'!H:H) -> Q2C-020-010 | N13: =_xlfn.XLOOKUP($H13,'Taxonomy and Epics'!$H:$H,'Taxonomy and Epics'!I:I) -> Establish Contract Portfolio Management
A14: US006 | B14: Processing a customer contract | C14: As an Accounts Receivable Officer, I want to create a new customer contract in Workday, so that billing and revenue can be managed according to agreed terms. | D14: - Given I have a valid contract request, when I use the 'Create Customer Contract' task, then I can enter all contract details, such as for a Property Rental Contract. - Given I submit the new contract, then it becomes active and available for a billing schedule to be created. | E14: Accounts Receivable Officer | F14: 0 | H14: Q2C-020-010 | I14: =_xlfn.XLOOKUP(H14,'Taxonomy and Epics'!H:H,'Taxonomy and Epics'!I:I) -> Establish Contract Portfolio Management | J14: =_xlfn.XLOOKUP($H14,'Taxonomy and Epics'!$H:$H,'Taxonomy and Epics'!E:E) -> 3.0 - Q2C - Quote to Cash | K14: =_xlfn.XLOOKUP($H14,'Taxonomy and Epics'!$H:$H,'Taxonomy and Epics'!F:F) -> Q2C-020 | L14: =_xlfn.XLOOKUP($H14,'Taxonomy and Epics'!$H:$H,'Taxonomy and Epics'!G:G) -> Contract Lifecycle Management (Customer) | M14: =_xlfn.XLOOKUP($H14,'Taxonomy and Epics'!$H:$H,'Taxonomy and Epics'!H:H) -> Q2C-020-010 | N14: =_xlfn.XLOOKUP($H14,'Taxonomy and Epics'!$H:$H,'Taxonomy and Epics'!I:I) -> Establish Contract Portfolio Management
A15: US007 | B15: processing a contract's billing schedule | C15: As an Accounts Receivable Officer, I want to create a billing schedule for a customer contract, so that invoices are generated automatically at the correct intervals. | D15: - Given I am a customer contract exists, when I create a billing schedule associated with the contract, then I can create a billing schedule which defines the billing frequency, amount, and dates. - Given the billing schedule is submitted, when a scheduled billing date arrives, then the system automatically generates the correct customer invoice. | E15: Accounts Receivable Officer | F15: 0 | H15: Q2C-020-010 | I15: =_xlfn.XLOOKUP(H15,'Taxonomy and Epics'!H:H,'Taxonomy and Epics'!I:I) -> Establish Contract Portfolio Management | J15: =_xlfn.XLOOKUP($H15,'Taxonomy and Epics'!$H:$H,'Taxonomy and Epics'!E:E) -> 3.0 - Q2C - Quote to Cash | K15: =_xlfn.XLOOKUP($H15,'Taxonomy and Epics'!$H:$H,'Taxonomy and Epics'!F:F) -> Q2C-020 | L15: =_xlfn.XLOOKUP($H15,'Taxonomy and Epics'!$H:$H,'Taxonomy and Epics'!G:G) -> Contract Lifecycle Management (Customer) | M15: =_xlfn.XLOOKUP($H15,'Taxonomy and Epics'!$H:$H,'Taxonomy and Epics'!H:H) -> Q2C-020-010 | N15: =_xlfn.XLOOKUP($H15,'Taxonomy and Epics'!$H:$H,'Taxonomy and Epics'!I:I) -> Establish Contract Portfolio Management
A16: US008 | B16: Processing a deferred revenue contract's deferred revenue schedule | C16: As a Revenue Specialist, I want to create a revenue recognition schedule for contracts with deferred revenue, so that revenue is recognised in the correct accounting period. | D16: - Given a customer contract is flagged for deferred revenue, when the contract is created, then the system prompts for the creation of a revenue recognition schedule. - Given I create a revenue recognition schedule according to a defined schedule, then the system will then automatically create and post revenue accounting journals each month. | E16: Revenue Specialist | F16: 0 | H16: Q2C-020-010 | I16: =_xlfn.XLOOKUP(H16,'Taxonomy and Epics'!H:H,'Taxonomy and Epics'!I:I) -> Establish Contract Portfolio Management | J16: =_xlfn.XLOOKUP($H16,'Taxonomy and Epics'!$H:$H,'Taxonomy and Epics'!E:E) -> 3.0 - Q2C - Quote to Cash | K16: =_xlfn.XLOOKUP($H16,'Taxonomy and Epics'!$H:$H,'Taxonomy and Epics'!F:F) -> Q2C-020 | L16: =_xlfn.XLOOKUP($H16,'Taxonomy and Epics'!$H:$H,'Taxonomy and Epics'!G:G) -> Contract Lifecycle Management (Customer) | M16: =_xlfn.XLOOKUP($H16,'Taxonomy and Epics'!$H:$H,'Taxonomy and Epics'!H:H) -> Q2C-020-010 | N16: =_xlfn.XLOOKUP($H16,'Taxonomy and Epics'!$H:$H,'Taxonomy and Epics'!I:I) -> Establish Contract Portfolio Management
A17: US009 | B17: amending an existing customer contract | C17: As an Accounts Receivable Officer, I want to amend an existing customer contract's value, so that the changes are reflected in the future billing schedule. | D17: - Given I am viewing an existing contract, when I initiate an amendment, then I can enter a change to the contract value (dollar amount). - Given I submit the amendment, then the future instalments on the associated billing schedule are updated to reflect the new total contract value. | E17: Accounts Receivable Officer | F17: 0 | H17: Q2C-020-030 | I17: =_xlfn.XLOOKUP(H17,'Taxonomy and Epics'!H:H,'Taxonomy and Epics'!I:I) -> Manage Contract Compliance and Administration | J17: =_xlfn.XLOOKUP($H17,'Taxonomy and Epics'!$H:$H,'Taxonomy and Epics'!E:E) -> 3.0 - Q2C - Quote to Cash | K17: =_xlfn.XLOOKUP($H17,'Taxonomy and Epics'!$H:$H,'Taxonomy and Epics'!F:F) -> Q2C-020 | L17: =_xlfn.XLOOKUP($H17,'Taxonomy and Epics'!$H:$H,'Taxonomy and Epics'!G:G) -> Contract Lifecycle Management (Customer) | M17: =_xlfn.XLOOKUP($H17,'Taxonomy and Epics'!$H:$H,'Taxonomy and Epics'!H:H) -> Q2C-020-030 | N17: =_xlfn.XLOOKUP($H17,'Taxonomy and Epics'!$H:$H,'Taxonomy and Epics'!I:I) -> Manage Contract Compliance and Administration
A18: US010 | B18: viewing fully billed contracts | C18: As an Accounts Receivable Officer, I want to view identify contracts that are fully billed, so that I can validate we are able to close a contract | D18: - Given I am viewing an existing contract, then it displays that the amount billed is the total of the contract and has no available installments remaining | E18: Accounts Receivable Officer | F18: 0 | H18: Q2C-020-040 | I18: =_xlfn.XLOOKUP(H18,'Taxonomy and Epics'!H:H,'Taxonomy and Epics'!I:I) -> Close Out Contract | J18: =_xlfn.XLOOKUP($H18,'Taxonomy and Epics'!$H:$H,'Taxonomy and Epics'!E:E) -> 3.0 - Q2C - Quote to Cash | K18: =_xlfn.XLOOKUP($H18,'Taxonomy and Epics'!$H:$H,'Taxonomy and Epics'!F:F) -> Q2C-020 | L18: =_xlfn.XLOOKUP($H18,'Taxonomy and Epics'!$H:$H,'Taxonomy and Epics'!G:G) -> Contract Lifecycle Management (Customer) | M18: =_xlfn.XLOOKUP($H18,'Taxonomy and Epics'!$H:$H,'Taxonomy and Epics'!H:H) -> Q2C-020-040 | N18: =_xlfn.XLOOKUP($H18,'Taxonomy and Epics'!$H:$H,'Taxonomy and Epics'!I:I) -> Close Out Contract
A19: US011 | B19: changing customer payment terms | C19: As an Accounts Receivable Officer, I want to change a customer's default payment terms, so that all future invoices for that customer reflect the new terms. | D19: - Given I am viewing a customer's record, when I edit their payment information, then I can select new payment terms. - Given I have submitted the new terms, when a new invoice is created for this customer, then its due date is calculated based on the new terms. | E19: Accounts Receivable Officer | F19: 0 | H19: Q2C-040-010 | I19: =_xlfn.XLOOKUP(H19,'Taxonomy and Epics'!H:H,'Taxonomy and Epics'!I:I) -> Manage Billing and Payment Methods | J19: =_xlfn.XLOOKUP($H19,'Taxonomy and Epics'!$H:$H,'Taxonomy and Epics'!E:E) -> 3.0 - Q2C - Quote to Cash | K19: =_xlfn.XLOOKUP($H19,'Taxonomy and Epics'!$H:$H,'Taxonomy and Epics'!F:F) -> Q2C-040 | L19: =_xlfn.XLOOKUP($H19,'Taxonomy and Epics'!$H:$H,'Taxonomy and Epics'!G:G) -> Billing Management | M19: =_xlfn.XLOOKUP($H19,'Taxonomy and Epics'!$H:$H,'Taxonomy and Epics'!H:H) -> Q2C-040-010 | N19: =_xlfn.XLOOKUP($H19,'Taxonomy and Epics'!$H:$H,'Taxonomy and Epics'!I:I) -> Manage Billing and Payment Methods
A20: US012 | B20: changing payment terms on a billling schedule | C20: As an Accounts Receivable Officer, I want to override the payment terms on a specific billing schedule, so that its invoices have different terms from the customer's default. | D20: - Given I am editing a billing schedule, when I change the payment terms, then I can set terms that are different from the customer's default. - Given I have submitted the schedule, when an invoice is generated from it, then its due date is based on the schedule's specific terms. | E20: Accounts Receivable Officer | F20: 0 | H20: Q2C-040-010 | I20: =_xlfn.XLOOKUP(H20,'Taxonomy and Epics'!H:H,'Taxonomy and Epics'!I:I) -> Manage Billing and Payment Methods | J20: =_xlfn.XLOOKUP($H20,'Taxonomy and Epics'!$H:$H,'Taxonomy and Epics'!E:E) -> 3.0 - Q2C - Quote to Cash | K20: =_xlfn.XLOOKUP($H20,'Taxonomy and Epics'!$H:$H,'Taxonomy and Epics'!F:F) -> Q2C-040 | L20: =_xlfn.XLOOKUP($H20,'Taxonomy and Epics'!$H:$H,'Taxonomy and Epics'!G:G) -> Billing Management | M20: =_xlfn.XLOOKUP($H20,'Taxonomy and Epics'!$H:$H,'Taxonomy and Epics'!H:H) -> Q2C-040-010 | N20: =_xlfn.XLOOKUP($H20,'Taxonomy and Epics'!$H:$H,'Taxonomy and Epics'!I:I) -> Manage Billing and Payment Methods
A21: US013 | B21: requesting a one-off invoice | C21: As a Business User, I want to request a one-off customer invoice via Service Now, so that the Accounts Receivable team can create it accurately in Workday. | D21: - Given I am in Service Now, when I open the 'Invoice Request' form, then I can enter all required details and attach supporting documents. - Given I submit the request, then it is routed to the Accounts Receivable team's queue for processing. | E21: Business User | F21: D.46 | H21: Q2C-040-020 | I21: =_xlfn.XLOOKUP(H21,'Taxonomy and Epics'!H:H,'Taxonomy and Epics'!I:I) -> Generate, Review & Approve Invoice | J21: =_xlfn.XLOOKUP($H21,'Taxonomy and Epics'!$H:$H,'Taxonomy and Epics'!E:E) -> 3.0 - Q2C - Quote to Cash | K21: =_xlfn.XLOOKUP($H21,'Taxonomy and Epics'!$H:$H,'Taxonomy and Epics'!F:F) -> Q2C-040 | L21: =_xlfn.XLOOKUP($H21,'Taxonomy and Epics'!$H:$H,'Taxonomy and Epics'!G:G) -> Billing Management | M21: =_xlfn.XLOOKUP($H21,'Taxonomy and Epics'!$H:$H,'Taxonomy and Epics'!H:H) -> Q2C-040-020 | N21: =_xlfn.XLOOKUP($H21,'Taxonomy and Epics'!$H:$H,'Taxonomy and Epics'!I:I) -> Generate, Review & Approve Invoice
A22: US014 | B22: processing a one-off invoice | C22: As an Accounts Receivable Officer, I want to create a standalone customer invoice, so that I can bill customers for items not covered by a contract. | D22: - Given I have a valid invoice request, when I use the 'Create Customer Invoice' task, then I can enter all details from the request. - Given I submit the invoice, then it is created and awaits approval before being sent. | E22: Accounts Receivable Officer | F22: D.45 | H22: Q2C-040-020 | I22: =_xlfn.XLOOKUP(H22,'Taxonomy and Epics'!H:H,'Taxonomy and Epics'!I:I) -> Generate, Review & Approve Invoice | J22: =_xlfn.XLOOKUP($H22,'Taxonomy and Epics'!$H:$H,'Taxonomy and Epics'!E:E) -> 3.0 - Q2C - Quote to Cash | K22: =_xlfn.XLOOKUP($H22,'Taxonomy and Epics'!$H:$H,'Taxonomy and Epics'!F:F) -> Q2C-040 | L22: =_xlfn.XLOOKUP($H22,'Taxonomy and Epics'!$H:$H,'Taxonomy and Epics'!G:G) -> Billing Management | M22: =_xlfn.XLOOKUP($H22,'Taxonomy and Epics'!$H:$H,'Taxonomy and Epics'!H:H) -> Q2C-040-020 | N22: =_xlfn.XLOOKUP($H22,'Taxonomy and Epics'!$H:$H,'Taxonomy and Epics'!I:I) -> Generate, Review & Approve Invoice
A23: US015 | B23: distributing attachments to a customer on an invoice | C23: As an Accounts Receivable Officer, I want to add attachments to an invoice and control their visibility, so that I can provide supporting documents to the customer or keep internal notes. | D23: - Given I am creating an invoice, when I add an attachment, then the system prompts me to choose if it is 'internal only' or 'provide to customer'. - Given an attachment is marked 'provide to customer', when the invoice is emailed, then the attachment is included. - Given an attachment is not marked 'provide to customer', when the invoice is emailed, then the attachment is not included. | E23: Accounts Receivable Officer | F23: 0 | H23: Q2C-040-020 | I23: =_xlfn.XLOOKUP(H23,'Taxonomy and Epics'!H:H,'Taxonomy and Epics'!I:I) -> Generate, Review & Approve Invoice | J23: =_xlfn.XLOOKUP($H23,'Taxonomy and Epics'!$H:$H,'Taxonomy and Epics'!E:E) -> 3.0 - Q2C - Quote to Cash | K23: =_xlfn.XLOOKUP($H23,'Taxonomy and Epics'!$H:$H,'Taxonomy and Epics'!F:F) -> Q2C-040 | L23: =_xlfn.XLOOKUP($H23,'Taxonomy and Epics'!$H:$H,'Taxonomy and Epics'!G:G) -> Billing Management | M23: =_xlfn.XLOOKUP($H23,'Taxonomy and Epics'!$H:$H,'Taxonomy and Epics'!H:H) -> Q2C-040-020 | N23: =_xlfn.XLOOKUP($H23,'Taxonomy and Epics'!$H:$H,'Taxonomy and Epics'!I:I) -> Generate, Review & Approve Invoice
A24: US016 | B24: Processing one off invoices with deferred revenue | C24: As a Revenue Specialist, I want a revenue recognition schedule created for any standalone invoice with deferred revenue, so that revenue is recognised in the correct periods. | D24: - Given an invoice is created with items flagged for deferred revenue, when it is submitted, then a To-Do task is created for me to create a revenue recognition schedule. | E24: Revenue Specialist | F24: D.63 | H24: Q2C-040-020 | I24: =_xlfn.XLOOKUP(H24,'Taxonomy and Epics'!H:H,'Taxonomy and Epics'!I:I) -> Generate, Review & Approve Invoice | J24: =_xlfn.XLOOKUP($H24,'Taxonomy and Epics'!$H:$H,'Taxonomy and Epics'!E:E) -> 3.0 - Q2C - Quote to Cash | K24: =_xlfn.XLOOKUP($H24,'Taxonomy and Epics'!$H:$H,'Taxonomy and Epics'!F:F) -> Q2C-040 | L24: =_xlfn.XLOOKUP($H24,'Taxonomy and Epics'!$H:$H,'Taxonomy and Epics'!G:G) -> Billing Management | M24: =_xlfn.XLOOKUP($H24,'Taxonomy and Epics'!$H:$H,'Taxonomy and Epics'!H:H) -> Q2C-040-020 | N24: =_xlfn.XLOOKUP($H24,'Taxonomy and Epics'!$H:$H,'Taxonomy and Epics'!I:I) -> Generate, Review & Approve Invoice
A25: US017 | B25: emailing invoices to a customer | C25: As an Accounts Receivable Officer, I want to email a finalised invoice to a customer, so that they receive it for payment. | D25: - Given an invoice is approved, when it is automatically processed, then a PDF copy is generated and stored in Workday. - Given the customer has a valid email, when I email the invoice, then it is sent to their primary billing contact. - Given the customer has no email address, when I review invoices scheduled to be emailed, then I can view a list of invoices which have not been emailed | E25: Accounts Receivable Officer | F25: 0 | H25: Q2C-040-030 | I25: =_xlfn.XLOOKUP(H25,'Taxonomy and Epics'!H:H,'Taxonomy and Epics'!I:I) -> Distribute Invoice | J25: =_xlfn.XLOOKUP($H25,'Taxonomy and Epics'!$H:$H,'Taxonomy and Epics'!E:E) -> 3.0 - Q2C - Quote to Cash | K25: =_xlfn.XLOOKUP($H25,'Taxonomy and Epics'!$H:$H,'Taxonomy and Epics'!F:F) -> Q2C-040 | L25: =_xlfn.XLOOKUP($H25,'Taxonomy and Epics'!$H:$H,'Taxonomy and Epics'!G:G) -> Billing Management | M25: =_xlfn.XLOOKUP($H25,'Taxonomy and Epics'!$H:$H,'Taxonomy and Epics'!H:H) -> Q2C-040-030 | N25: =_xlfn.XLOOKUP($H25,'Taxonomy and Epics'!$H:$H,'Taxonomy and Epics'!I:I) -> Distribute Invoice
A26: US018 | B26: generating an invoice but not emailing it | C26: As an Accounts Receivable Officer, I want to generate a PDF of an invoice without emailing it, so that I can print it or send it through other channels. | D26: - Given an invoice is marked as "Do Not Send", when the invoice is approved, the invoice Print Run and Email Steps are not triggered. Given an invoice is marked as "Do Not Send", when I select the 'Print Invoice' action, then the system creates a PDF for download without sending an email. | E26: Accounts Receivable Officer | F26: 0 | H26: Q2C-040-030 | I26: =_xlfn.XLOOKUP(H26,'Taxonomy and Epics'!H:H,'Taxonomy and Epics'!I:I) -> Distribute Invoice | J26: =_xlfn.XLOOKUP($H26,'Taxonomy and Epics'!$H:$H,'Taxonomy and Epics'!E:E) -> 3.0 - Q2C - Quote to Cash | K26: =_xlfn.XLOOKUP($H26,'Taxonomy and Epics'!$H:$H,'Taxonomy and Epics'!F:F) -> Q2C-040 | L26: =_xlfn.XLOOKUP($H26,'Taxonomy and Epics'!$H:$H,'Taxonomy and Epics'!G:G) -> Billing Management | M26: =_xlfn.XLOOKUP($H26,'Taxonomy and Epics'!$H:$H,'Taxonomy and Epics'!H:H) -> Q2C-040-030 | N26: =_xlfn.XLOOKUP($H26,'Taxonomy and Epics'!$H:$H,'Taxonomy and Epics'!I:I) -> Distribute Invoice
A27: US019 | B27: updating the PO on a customer invoice | C27: As an Accounts Receivable Officer, I want to add or change the Purchase Order (PO) number on an existing invoice, so that it reflects the correct customer reference. | D27: - Given I am viewing a created invoice, when I edit it, then I can update the PO number field. - Given I have updated the PO number, when I regenerate the invoice PDF, then the new PO number is displayed on the document. | E27: Accounts Receivable Officer | F27: 0 | H27: Q2C-040-030 | I27: =_xlfn.XLOOKUP(H27,'Taxonomy and Epics'!H:H,'Taxonomy and Epics'!I:I) -> Distribute Invoice | J27: =_xlfn.XLOOKUP($H27,'Taxonomy and Epics'!$H:$H,'Taxonomy and Epics'!E:E) -> 3.0 - Q2C - Quote to Cash | K27: =_xlfn.XLOOKUP($H27,'Taxonomy and Epics'!$H:$H,'Taxonomy and Epics'!F:F) -> Q2C-040 | L27: =_xlfn.XLOOKUP($H27,'Taxonomy and Epics'!$H:$H,'Taxonomy and Epics'!G:G) -> Billing Management | M27: =_xlfn.XLOOKUP($H27,'Taxonomy and Epics'!$H:$H,'Taxonomy and Epics'!H:H) -> Q2C-040-030 | N27: =_xlfn.XLOOKUP($H27,'Taxonomy and Epics'!$H:$H,'Taxonomy and Epics'!I:I) -> Distribute Invoice
A28: US020 | B28: scheduling customer statements | C28: As an Accounts Receivable Officer, I want to schedule the automatic monthly delivery of customer statements, so that customers are regularly informed of their account status. | D28: - Given I am configuring statement schedules, when I set up a schedule, then I can select a monthly frequency. - Given the schedule is active, when the scheduled day arrives, then the system automatically generates and emails statements to eligible customers. | E28: Accounts Receivable Officer | F28: D.47 | H28: Q2C-040-040 | I28: =_xlfn.XLOOKUP(H28,'Taxonomy and Epics'!H:H,'Taxonomy and Epics'!I:I) -> Generate and Distribute Statements | J28: =_xlfn.XLOOKUP($H28,'Taxonomy and Epics'!$H:$H,'Taxonomy and Epics'!E:E) -> 3.0 - Q2C - Quote to Cash | K28: =_xlfn.XLOOKUP($H28,'Taxonomy and Epics'!$H:$H,'Taxonomy and Epics'!F:F) -> Q2C-040 | L28: =_xlfn.XLOOKUP($H28,'Taxonomy and Epics'!$H:$H,'Taxonomy and Epics'!G:G) -> Billing Management | M28: =_xlfn.XLOOKUP($H28,'Taxonomy and Epics'!$H:$H,'Taxonomy and Epics'!H:H) -> Q2C-040-040 | N28: =_xlfn.XLOOKUP($H28,'Taxonomy and Epics'!$H:$H,'Taxonomy and Epics'!I:I) -> Generate and Distribute Statements
A29: US021 | B29: generate a customer statement | C29: As an Accounts Receivable Officer, I want to generate and manually email a customer statement on-demand, so that customers are regularly informed of their account status. | D29: - Given I am sending customer statements to eligible customers, when I select 'Print Customer Statement', then the system produces a statement of open items. - Given the statement is generated, when I review the customer statement, then I can optionally email the statement to the customer. | E29: Accounts Receivable Officer | F29: D.47 | H29: Q2C-040-040 | I29: =_xlfn.XLOOKUP(H29,'Taxonomy and Epics'!H:H,'Taxonomy and Epics'!I:I) -> Generate and Distribute Statements | J29: =_xlfn.XLOOKUP($H29,'Taxonomy and Epics'!$H:$H,'Taxonomy and Epics'!E:E) -> 3.0 - Q2C - Quote to Cash | K29: =_xlfn.XLOOKUP($H29,'Taxonomy and Epics'!$H:$H,'Taxonomy and Epics'!F:F) -> Q2C-040 | L29: =_xlfn.XLOOKUP($H29,'Taxonomy and Epics'!$H:$H,'Taxonomy and Epics'!G:G) -> Billing Management | M29: =_xlfn.XLOOKUP($H29,'Taxonomy and Epics'!$H:$H,'Taxonomy and Epics'!H:H) -> Q2C-040-040 | N29: =_xlfn.XLOOKUP($H29,'Taxonomy and Epics'!$H:$H,'Taxonomy and Epics'!I:I) -> Generate and Distribute Statements
A30: US022 | B30: placing invoices in dispute | C30: As a Credit Officer, I want to place one or more invoices in dispute, so that they are excluded from collection activities while the issue is investigated. | D30: - Given I select one invoice and choose the 'Maintain Dispute' action, then the system displays a dispute date, dispute reason and notes. - Given I initiate the "Manage Customer Invoices" task and select one or more invoices and choose the 'Maintain Dispute' action, then the system displays a dispute date, dispute reason and note. - Given an invoice is marked 'In Dispute', then its status is clearly shown as 'Disputed' and it is excluded from the dunning process. | E30: Credit Officer | F30: 0 | H30: Q2C-050-010 | I30: =_xlfn.XLOOKUP(H30,'Taxonomy and Epics'!H:H,'Taxonomy and Epics'!I:I) -> Manage Customer Service Inquiry and Orders | J30: =_xlfn.XLOOKUP($H30,'Taxonomy and Epics'!$H:$H,'Taxonomy and Epics'!E:E) -> 3.0 - Q2C - Quote to Cash | K30: =_xlfn.XLOOKUP($H30,'Taxonomy and Epics'!$H:$H,'Taxonomy and Epics'!F:F) -> Q2C-050 | L30: =_xlfn.XLOOKUP($H30,'Taxonomy and Epics'!$H:$H,'Taxonomy and Epics'!G:G) -> Customer Inquiry and Dispute | M30: =_xlfn.XLOOKUP($H30,'Taxonomy and Epics'!$H:$H,'Taxonomy and Epics'!H:H) -> Q2C-050-010 | N30: =_xlfn.XLOOKUP($H30,'Taxonomy and Epics'!$H:$H,'Taxonomy and Epics'!I:I) -> Manage Customer Service Inquiry and Orders
A31: US023 | B31: removing invoices from dispute | C31: As a Credit Officer, I want to resolve a dispute on an invoice, so that it can be returned to the normal collections process or be credited. | D31: - Given an invoice is marked as 'In Dispute', when I mark the invoice as resolved , then its status is no longer marked as disputed. | E31: Credit Officer | F31: 0 | H31: Q2C-050-010 | I31: =_xlfn.XLOOKUP(H31,'Taxonomy and Epics'!H:H,'Taxonomy and Epics'!I:I) -> Manage Customer Service Inquiry and Orders | J31: =_xlfn.XLOOKUP($H31,'Taxonomy and Epics'!$H:$H,'Taxonomy and Epics'!E:E) -> 3.0 - Q2C - Quote to Cash | K31: =_xlfn.XLOOKUP($H31,'Taxonomy and Epics'!$H:$H,'Taxonomy and Epics'!F:F) -> Q2C-050 | L31: =_xlfn.XLOOKUP($H31,'Taxonomy and Epics'!$H:$H,'Taxonomy and Epics'!G:G) -> Customer Inquiry and Dispute | M31: =_xlfn.XLOOKUP($H31,'Taxonomy and Epics'!$H:$H,'Taxonomy and Epics'!H:H) -> Q2C-050-010 | N31: =_xlfn.XLOOKUP($H31,'Taxonomy and Epics'!$H:$H,'Taxonomy and Epics'!I:I) -> Manage Customer Service Inquiry and Orders
